{"text": "2022-11-17T09:54:20.351315+0400 ERROR An error has been caught in function '__call__', process 'MainProcess' (13668), thread 'MainThread' (10104):\nTraceback (most recent call last):\n\n  File \"d:\\Python GB\\Project_calculator\\user_interface.py\", line 132, in <module>\n    win.mainloop()\n    │   └ <function Misc.mainloop at 0x000002CEA586DEA0>\n    └ <tkinter.Tk object .>\n\n  File \"D:\\Python GB\\Python\\lib\\tkinter\\__init__.py\", line 1458, in mainloop\n    self.tk.mainloop(n)\n    │    │  │        └ 0\n    │    │  └ <method 'mainloop' of '_tkinter.tkapp' objects>\n    │    └ <_tkinter.tkapp object at 0x000002CEA7AE1030>\n    └ <tkinter.Tk object .>\n\n> File \"D:\\Python GB\\Python\\lib\\tkinter\\__init__.py\", line 1921, in __call__\n    return self.func(*args)\n           │    │     └ ()\n           │    └ <function calculate at 0x000002CEA7B2B010>\n           └ <tkinter.CallWrapper object at 0x000002CEA7B3A2F0>\n\n  File \"d:\\Python GB\\Project_calculator\\user_interface.py\", line 45, in calculate\n    calc.insert(0, eval(value))\n    │    │              └ '3/0'\n    │    └ <function Entry.insert at 0x000002CEA5874160>\n    └ <tkinter.Entry object .!entry>\n\n  File \"<string>\", line 1, in <module>\n\nZeroDivisionError: division by zero\n", "record": {"elapsed": {"repr": "0:00:03.901034", "seconds": 3.901034}, "exception": {"type": "ZeroDivisionError", "value": "division by zero", "traceback": true}, "extra": {}, "file": {"name": "__init__.py", "path": "D:\\Python GB\\Python\\lib\\tkinter\\__init__.py"}, "function": "__call__", "level": {"icon": "❌", "name": "ERROR", "no": 40}, "line": 1921, "message": "An error has been caught in function '__call__', process 'MainProcess' (13668), thread 'MainThread' (10104):", "module": "__init__", "name": "tkinter", "process": {"id": 13668, "name": "MainProcess"}, "thread": {"id": 10104, "name": "MainThread"}, "time": {"repr": "2022-11-17 09:54:20.351315+04:00", "timestamp": 1668664460.351315}}}
